Workbook

Sheet 原始数据
A1: 计信院学生第X周入班听课汇总表
A2: 基本信息 | E2: 考勤信息 | M2: 上课状态 | U2: 其他
A3: 年级 | B3: 听课班级 | C3: 课程名称 | D3: 课程性质 | E3: 应到 | F3: 实到 | G3: 未到 | H3: 出勤率 | I3: 迟到 | J3: 比例 | K3: 早退 | L3: 比例 | M3: 睡觉 | N3: 比例 | O3: 玩手机 | P3: 比例 | Q3: 说话 | R3: 比例 | S3: 违纪情况 | T3: 比例 | U3: 其他情况 | V3: 人数 | W3: 比例 | X3: 听课组员对班风评价 | Y3: 异常情况及反馈 | Z3: 任课教师对班级学风建设的意见及建议
A4: 25 | B4: 25计科1/2 | G4: =IF(E4<>-1,E4-F4,-1) -> 0 | H4: =F4/E4 -> #DIV/0! | J4: =I4/F4 -> #DIV/0! | L4: =K4/E4 -> #DIV/0! | N4: =M4/F4 -> #DIV/0! | P4: =O4/F4 -> #DIV/0! | R4: =Q4/F4 -> #DIV/0! | S4: =IF(OR(M4=-1,O4=-1,Q4=-1),-1,SUM(M4,O4,Q4)) -> 0 | T4: =S4/F4 -> #DIV/0! | W4: =V4/F4 -> #DIV/0!
B5: 25计科3/4 | G5: =IF(E5<>-1,E5-F5,-1) -> 0 | H5: =F5/E5 -> #DIV/0! | J5: =I5/F5 -> #DIV/0! | L5: =K5/E5 -> #DIV/0! | N5: =M5/F5 -> #DIV/0! | P5: =O5/F5 -> #DIV/0! | R5: =Q5/F5 -> #DIV/0! | S5: =IF(OR(M5=-1,O5=-1,Q5=-1),-1,SUM(M5,O5,Q5)) -> 0 | T5: =S5/F5 -> #DIV/0! | W5: =V5/F5 -> #DIV/0!
B6: 25计师1 | G6: =IF(E6<>-1,E6-F6,-1) -> 0 | H6: =F6/E6 -> #DIV/0! | J6: =I6/F6 -> #DIV/0! | L6: =K6/E6 -> #DIV/0! | N6: =M6/F6 -> #DIV/0! | P6: =O6/F6 -> #DIV/0! | R6: =Q6/F6 -> #DIV/0! | S6: =IF(OR(M6=-1,O6=-1,Q6=-1),-1,SUM(M6,O6,Q6)) -> 0 | T6: =S6/F6 -> #DIV/0! | W6: =V6/F6 -> #DIV/0!
B7: 25计师2 | G7: =IF(E7<>-1,E7-F7,-1) -> 0 | H7: =F7/E7 -> #DIV/0! | J7: =I7/F7 -> #DIV/0! | L7: =K7/E7 -> #DIV/0! | N7: =M7/F7 -> #DIV/0! | P7: =O7/F7 -> #DIV/0! | R7: =Q7/F7 -> #DIV/0! | S7: =IF(OR(M7=-1,O7=-1,Q7=-1),-1,SUM(M7,O7,Q7)) -> 0 | T7: =S7/F7 -> #DIV/0! | W7: =V7/F7 -> #DIV/0!
B8: 25计创1/2 | G8: =IF(E8<>-1,E8-F8,-1) -> 0 | H8: =F8/E8 -> #DIV/0! | J8: =I8/F8 -> #DIV/0! | L8: =K8/E8 -> #DIV/0! | N8: =M8/F8 -> #DIV/0! | P8: =O8/F8 -> #DIV/0! | R8: =Q8/F8 -> #DIV/0! | S8: =IF(OR(M8=-1,O8=-1,Q8=-1),-1,SUM(M8,O8,Q8)) -> 0 | T8: =S8/F8 -> #DIV/0! | W8: =V8/F8 -> #DIV/0!
B9: 25计创3/4 | G9: =IF(E9<>-1,E9-F9,-1) -> 0 | H9: =F9/E9 -> #DIV/0! | J9: =I9/F9 -> #DIV/0! | L9: =K9/E9 -> #DIV/0! | N9: =M9/F9 -> #DIV/0! | P9: =O9/F9 -> #DIV/0! | R9: =Q9/F9 -> #DIV/0! | S9: =IF(OR(M9=-1,O9=-1,Q9=-1),-1,SUM(M9,O9,Q9)) -> 0 | T9: =S9/F9 -> #DIV/0! | W9: =V9/F9 -> #DIV/0!
B10: 25软工1/2 | G10: =IF(E10<>-1,E10-F10,-1) -> 0 | H10: =F10/E10 -> #DIV/0! | J10: =I10/F10 -> #DIV/0! | L10: =K10/E10 -> #DIV/0! | N10: =M10/F10 -> #DIV/0! | P10: =O10/F10 -> #DIV/0! | R10: =Q10/F10 -> #DIV/0! | S10: =IF(OR(M10=-1,O10=-1,Q10=-1),-1,SUM(M10,O10,Q10)) -> 0 | T10: =S10/F10 -> #DIV/0! | W10: =V10/F10 -> #DIV/0!
B11: 25软工3/4 | G11: =IF(E11<>-1,E11-F11,-1) -> 0 | H11: =F11/E11 -> #DIV/0! | J11: =I11/F11 -> #DIV/0! | L11: =K11/E11 -> #DIV/0! | N11: =M11/F11 -> #DIV/0! | P11: =O11/F11 -> #DIV/0! | R11: =Q11/F11 -> #DIV/0! | S11: =IF(OR(M11=-1,O11=-1,Q11=-1),-1,SUM(M11,O11,Q11)) -> 0 | T11: =S11/F11 -> #DIV/0! | W11: =V11/F11 -> #DIV/0!
B12: 25软普1/2 | G12: =IF(E12<>-1,E12-F12,-1) -> 0 | H12: =F12/E12 -> #DIV/0! | J12: =I12/F12 -> #DIV/0! | L12: =K12/E12 -> #DIV/0! | N12: =M12/F12 -> #DIV/0! | P12: =O12/F12 -> #DIV/0! | R12: =Q12/F12 -> #DIV/0! | S12: =IF(OR(M12=-1,O12=-1,Q12=-1),-1,SUM(M12,O12,Q12)) -> 0 | T12: =S12/F12 -> #DIV/0! | W12: =V12/F12 -> #DIV/0!
B13: 25软普3/4 | G13: =IF(E13<>-1,E13-F13,-1) -> 0 | H13: =F13/E13 -> #DIV/0! | J13: =I13/F13 -> #DIV/0! | L13: =K13/E13 -> #DIV/0! | N13: =M13/F13 -> #DIV/0! | P13: =O13/F13 -> #DIV/0! | R13: =Q13/F13 -> #DIV/0! | S13: =IF(OR(M13=-1,O13=-1,Q13=-1),-1,SUM(M13,O13,Q13)) -> 0 | T13: =S13/F13 -> #DIV/0! | W13: =V13/F13 -> #DIV/0!
B14: 25自动化1/2 | G14: =IF(E14<>-1,E14-F14,-1) -> 0 | H14: =F14/E14 -> #DIV/0! | J14: =I14/F14 -> #DIV/0! | L14: =K14/E14 -> #DIV/0! | N14: =M14/F14 -> #DIV/0! | P14: =O14/F14 -> #DIV/0! | R14: =Q14/F14 -> #DIV/0! | S14: =IF(OR(M14=-1,O14=-1,Q14=-1),-1,SUM(M14,O14,Q14)) -> 0 | T14: =S14/F14 -> #DIV/0! | W14: =V14/F14 -> #DIV/0!
B15: 25自动化3/4 | G15: =IF(E15<>-1,E15-F15,-1) -> 0 | H15: =F15/E15 -> #DIV/0! | J15: =I15/F15 -> #DIV/0! | L15: =K15/E15 -> #DIV/0! | N15: =M15/F15 -> #DIV/0! | P15: =O15/F15 -> #DIV/0! | R15: =Q15/F15 -> #DIV/0! | S15: =IF(OR(M15=-1,O15=-1,Q15=-1),-1,SUM(M15,O15,Q15)) -> 0 | T15: =S15/F15 -> #DIV/0! | W15: =V15/F15 -> #DIV/0!
A16: 23 | B16: 23计科1/2 | G16: =IF(E16<>-1,E16-F16,-1) -> 0 | H16: =F16/E16 -> #DIV/0! | J16: =I16/F16 -> #DIV/0! | L16: =K16/E16 -> #DIV/0! | N16: =M16/F16 -> #DIV/0! | P16: =O16/F16 -> #DIV/0! | R16: =Q16/F16 -> #DIV/0! | S16: =IF(OR(M16=-1,O16=-1,Q16=-1),-1,SUM(M16,O16,Q16)) -> 0 | T16: =S16/F16 -> #DIV/0! | W16: =V16/F16 -> #DIV/0!
B17: 23计科3/4 | G17: =IF(E17<>-1,E17-F17,-1) -> 0 | H17: =F17/E17 -> #DIV/0! | J17: =I17/F17 -> #DIV/0! | L17: =K17/E17 -> #DIV/0! | N17: =M17/F17 -> #DIV/0! | P17: =O17/F17 -> #DIV/0! | R17: =Q17/F17 -> #DIV/0! | S17: =IF(OR(M17=-1,O17=-1,Q17=-1),-1,SUM(M17,O17,Q17)) -> 0 | T17: =S17/F17 -> #DIV/0! | W17: =V17/F17 -> #DIV/0!
B18: 23计师1 | G18: =IF(E18<>-1,E18-F18,-1) -> 0 | H18: =F18/E18 -> #DIV/0! | J18: =I18/F18 -> #DIV/0! | L18: =K18/E18 -> #DIV/0! | N18: =M18/F18 -> #DIV/0! | P18: =O18/F18 -> #DIV/0! | R18: =Q18/F18 -> #DIV/0! | S18: =IF(OR(M18=-1,O18=-1,Q18=-1),-1,SUM(M18,O18,Q18)) -> 0 | T18: =S18/F18 -> #DIV/0! | W18: =V18/F18 -> #DIV/0!
B19: 23计师2 | G19: =IF(E19<>-1,E19-F19,-1) -> 0 | H19: =F19/E19 -> #DIV/0! | J19: =I19/F19 -> #DIV/0! | L19: =K19/E19 -> #DIV/0! | N19: =M19/F19 -> #DIV/0! | P19: =O19/F19 -> #DIV/0! | R19: =Q19/F19 -> #DIV/0! | S19: =IF(OR(M19=-1,O19=-1,Q19=-1),-1,SUM(M19,O19,Q19)) -> 0 | T19: =S19/F19 -> #DIV/0! | W19: =V19/F19 -> #DIV/0!
B20: 23计创1 | G20: =IF(E20<>-1,E20-F20,-1) -> 0 | H20: =F20/E20 -> #DIV/0! | J20: =I20/F20 -> #DIV/0! | L20: =K20/E20 -> #DIV/0! | N20: =M20/F20 -> #DIV/0! | P20: =O20/F20 -> #DIV/0! | R20: =Q20/F20 -> #DIV/0! | S20: =IF(OR(M20=-1,O20=-1,Q20=-1),-1,SUM(M20,O20,Q20)) -> 0 | T20: =S20/F20 -> #DIV/0! | W20: =V20/F20 -> #DIV/0!
B21: 23计创2 | G21: =IF(E21<>-1,E21-F21,-1) -> 0 | H21: =F21/E21 -> #DIV/0! | J21: =I21/F21 -> #DIV/0! | L21: =K21/E21 -> #DIV/0! | N21: =M21/F21 -> #DIV/0! | P21: =O21/F21 -> #DIV/0! | R21: =Q21/F21 -> #DIV/0! | S21: =IF(OR(M21=-1,O21=-1,Q21=-1),-1,SUM(M21,O21,Q21)) -> 0 | T21: =S21/F21 -> #DIV/0! | W21: =V21/F21 -> #DIV/0!
B22: 23网工1/2 | G22: =IF(E22<>-1,E22-F22,-1) -> 0 | H22: =F22/E22 -> #DIV/0! | J22: =I22/F22 -> #DIV/0! | L22: =K22/E22 -> #DIV/0! | N22: =M22/F22 -> #DIV/0! | P22: =O22/F22 -> #DIV/0! | R22: =Q22/F22 -> #DIV/0! | S22: =IF(OR(M22=-1,O22=-1,Q22=-1),-1,SUM(M22,O22,Q22)) -> 0 | T22: =S22/F22 -> #DIV/0! | W22: =V22/F22 -> #DIV/0!
B23: 23软工1/2 | G23: =IF(E23<>-1,E23-F23,-1) -> 0 | H23: =F23/E23 -> #DIV/0! | J23: =I23/F23 -> #DIV/0! | L23: =K23/E23 -> #DIV/0! | N23: =M23/F23 -> #DIV/0! | P23: =O23/F23 -> #DIV/0! | R23: =Q23/F23 -> #DIV/0! | S23: =IF(OR(M23=-1,O23=-1,Q23=-1),-1,SUM(M23,O23,Q23)) -> 0 | T23: =S23/F23 -> #DIV/0! | W23: =V23/F23 -> #DIV/0!
B24: 23软工3/4 | G24: =IF(E24<>-1,E24-F24,-1) -> 0 | H24: =F24/E24 -> #DIV/0! | J24: =I24/F24 -> #DIV/0! | L24: =K24/E24 -> #DIV/0! | N24: =M24/F24 -> #DIV/0! | P24: =O24/F24 -> #DIV/0! | R24: =Q24/F24 -> #DIV/0! | S24: =IF(OR(M24=-1,O24=-1,Q24=-1),-1,SUM(M24,O24,Q24)) -> 0 | T24: =S24/F24 -> #DIV/0! | W24: =V24/F24 -> #DIV/0!
B25: 23软普1/2 | G25: =IF(E25<>-1,E25-F25,-1) -> 0 | H25: =F25/E25 -> #DIV/0! | J25: =I25/F25 -> #DIV/0! | L25: =K25/E25 -> #DIV/0! | N25: =M25/F25 -> #DIV/0! | P25: =O25/F25 -> #DIV/0! | R25: =Q25/F25 -> #DIV/0! | S25: =IF(OR(M25=-1,O25=-1,Q25=-1),-1,SUM(M25,O25,Q25)) -> 0 | T25: =S25/F25 -> #DIV/0! | W25: =V25/F25 -> #DIV/0!
B26: 23软普3/4 | G26: =IF(E26<>-1,E26-F26,-1) -> 0 | H26: =F26/E26 -> #DIV/0! | J26: =I26/F26 -> #DIV/0! | L26: =K26/E26 -> #DIV/0! | N26: =M26/F26 -> #DIV/0! | P26: =O26/F26 -> #DIV/0! | R26: =Q26/F26 -> #DIV/0! | S26: =IF(OR(M26=-1,O26=-1,Q26=-1),-1,SUM(M26,O26,Q26)) -> 0 | T26: =S26/F26 -> #DIV/0! | W26: =V26/F26 -> #DIV/0!
B27: 23自动化1/2 | G27: =IF(E27<>-1,E27-F27,-1) -> 0 | H27: =F27/E27 -> #DIV/0! | J27: =I27/F27 -> #DIV/0! | L27: =K27/E27 -> #DIV/0! | N27: =M27/F27 -> #DIV/0! | P27: =O27/F27 -> #DIV/0! | R27: =Q27/F27 -> #DIV/0! | S27: =IF(OR(M27=-1,O27=-1,Q27=-1),-1,SUM(M27,O27,Q27)) -> 0 | T27: =S27/F27 -> #DIV/0! | W27: =V27/F27 -> #DIV/0!
B28: 23自动化3/4 | G28: =IF(E28<>-1,E28-F28,-1) -> 0 | H28: =F28/E28 -> #DIV/0! | J28: =I28/F28 -> #DIV/0! | L28: =K28/E28 -> #DIV/0! | N28: =M28/F28 -> #DIV/0! | P28: =O28/F28 -> #DIV/0! | R28: =Q28/F28 -> #DIV/0! | S28: =IF(OR(M28=-1,O28=-1,Q28=-1),-1,SUM(M28,O28,Q28)) -> 0 | T28: =S28/F28 -> #DIV/0! | W28: =V28/F28 -> #DIV/0!
A29: 24 | B29: 24计科1/2 | G29: =IF(E29<>-1,E29-F29,-1) -> 0 | H29: =F29/E29 -> #DIV/0! | J29: =I29/F29 -> #DIV/0! | L29: =K29/E29 -> #DIV/0! | N29: =M29/F29 -> #DIV/0! | P29: =O29/F29 -> #DIV/0! | R29: =Q29/F29 -> #DIV/0! | S29: =IF(OR(M29=-1,O29=-1,Q29=-1),-1,SUM(M29,O29,Q29)) -> 0 | T29: =S29/F29 -> #DIV/0! | W29: =V29/F29 -> #DIV/0!
B30: 24计科3/4 | G30: =IF(E30<>-1,E30-F30,-1) -> 0 | H30: =F30/E30 -> #DIV/0! | J30: =I30/F30 -> #DIV/0! | L30: =K30/E30 -> #DIV/0! | N30: =M30/F30 -> #DIV/0! | P30: =O30/F30 -> #DIV/0! | R30: =Q30/F30 -> #DIV/0! | S30: =IF(OR(M30=-1,O30=-1,Q30=-1),-1,SUM(M30,O30,Q30)) -> 0 | T30: =S30/F30 -> #DIV/0! | W30: =V30/F30 -> #DIV/0!
B31: 24计师1 | G31: =IF(E31<>-1,E31-F31,-1) -> 0 | H31: =F31/E31 -> #DIV/0! | J31: =I31/F31 -> #DIV/0! | L31: =K31/E31 -> #DIV/0! | N31: =M31/F31 -> #DIV/0! | P31: =O31/F31 -> #DIV/0! | R31: =Q31/F31 -> #DIV/0! | S31: =IF(OR(M31=-1,O31=-1,Q31=-1),-1,SUM(M31,O31,Q31)) -> 0 | T31: =S31/F31 -> #DIV/0! | W31: =V31/F31 -> #DIV/0!
B32: 24计师2 | G32: =IF(E32<>-1,E32-F32,-1) -> 0 | H32: =F32/E32 -> #DIV/0! | J32: =I32/F32 -> #DIV/0! | L32: =K32/E32 -> #DIV/0! | N32: =M32/F32 -> #DIV/0! | P32: =O32/F32 -> #DIV/0! | R32: =Q32/F32 -> #DIV/0! | S32: =IF(OR(M32=-1,O32=-1,Q32=-1),-1,SUM(M32,O32,Q32)) -> 0 | T32: =S32/F32 -> #DIV/0! | W32: =V32/F32 -> #DIV/0!
B33: 24计创1 | G33: =IF(E33<>-1,E33-F33,-1) -> 0 | H33: =F33/E33 -> #DIV/0! | J33: =I33/F33 -> #DIV/0! | L33: =K33/E33 -> #DIV/0! | N33: =M33/F33 -> #DIV/0! | P33: =O33/F33 -> #DIV/0! | R33: =Q33/F33 -> #DIV/0! | S33: =IF(OR(M33=-1,O33=-1,Q33=-1),-1,SUM(M33,O33,Q33)) -> 0 | T33: =S33/F33 -> #DIV/0! | W33: =V33/F33 -> #DIV/0!
B34: 24计创2 | G34: =IF(E34<>-1,E34-F34,-1) -> 0 | H34: =F34/E34 -> #DIV/0! | J34: =I34/F34 -> #DIV/0! | L34: =K34/E34 -> #DIV/0! | N34: =M34/F34 -> #DIV/0! | P34: =O34/F34 -> #DIV/0! | R34: =Q34/F34 -> #DIV/0! | S34: =IF(OR(M34=-1,O34=-1,Q34=-1),-1,SUM(M34,O34,Q34)) -> 0 | T34: =S34/F34 -> #DIV/0! | W34: =V34/F34 -> #DIV/0!
B35: 24网工1/2 | G35: =IF(E35<>-1,E35-F35,-1) -> 0 | H35: =F35/E35 -> #DIV/0! | J35: =I35/F35 -> #DIV/0! | L35: =K35/E35 -> #DIV/0! | N35: =M35/F35 -> #DIV/0! | P35: =O35/F35 -> #DIV/0! | R35: =Q35/F35 -> #DIV/0! | S35: =IF(OR(M35=-1,O35=-1,Q35=-1),-1,SUM(M35,O35,Q35)) -> 0 | T35: =S35/F35 -> #DIV/0! | W35: =V35/F35 -> #DIV/0!
B36: 24自动化1/2 | G36: =IF(E36<>-1,E36-F36,-1) -> 0 | H36: =F36/E36 -> #DIV/0! | J36: =I36/F36 -> #DIV/0! | L36: =K36/E36 -> #DIV/0! | N36: =M36/F36 -> #DIV/0! | P36: =O36/F36 -> #DIV/0! | R36: =Q36/F36 -> #DIV/0! | S36: =IF(OR(M36=-1,O36=-1,Q36=-1),-1,SUM(M36,O36,Q36)) -> 0 | T36: =S36/F36 -> #DIV/0! | W36: =V36/F36 -> #DIV/0!
B37: 24自动化3/4 | G37: =IF(E37<>-1,E37-F37,-1) -> 0 | H37: =F37/E37 -> #DIV/0! | J37: =I37/F37 -> #DIV/0! | L37: =K37/E37 -> #DIV/0! | N37: =M37/F37 -> #DIV/0! | P37: =O37/F37 -> #DIV/0! | R37: =Q37/F37 -> #DIV/0! | S37: =IF(OR(M37=-1,O37=-1,Q37=-1),-1,SUM(M37,O37,Q37)) -> 0 | T37: =S37/F37 -> #DIV/0! | W37: =V37/F37 -> #DIV/0!
B38: 24软普3/4 | G38: =IF(E38<>-1,E38-F38,-1) -> 0 | H38: =F38/E38 -> #DIV/0! | J38: =I38/F38 -> #DIV/0! | L38: =K38/E38 -> #DIV/0! | N38: =M38/F38 -> #DIV/0! | P38: =O38/F38 -> #DIV/0! | R38: =Q38/F38 -> #DIV/0! | S38: =IF(OR(M38=-1,O38=-1,Q38=-1),-1,SUM(M38,O38,Q38)) -> 0 | T38: =S38/F38 -> #DIV/0! | W38: =V38/F38 -> #DIV/0!
B39: 24软普1/2 | G39: =IF(E39<>-1,E39-F39,-1) -> 0 | H39: =F39/E39 -> #DIV/0! | J39: =I39/F39 -> #DIV/0! | L39: =K39/E39 -> #DIV/0! | N39: =M39/F39 -> #DIV/0! | P39: =O39/F39 -> #DIV/0! | R39: =Q39/F39 -> #DIV/0! | S39: =IF(OR(M39=-1,O39=-1,Q39=-1),-1,SUM(M39,O39,Q39)) -> 0 | T39: =S39/F39 -> #DIV/0! | W39: =V39/F39 -> #DIV/0!
B40: 24软工1/2 | G40: =IF(E40<>-1,E40-F40,-1) -> 0 | H40: =F40/E40 -> #DIV/0! | J40: =I40/F40 -> #DIV/0! | L40: =K40/E40 -> #DIV/0! | N40: =M40/F40 -> #DIV/0! | P40: =O40/F40 -> #DIV/0! | R40: =Q40/F40 -> #DIV/0! | S40: =IF(OR(M40=-1,O40=-1,Q40=-1),-1,SUM(M40,O40,Q40)) -> 0 | T40: =S40/F40 -> #DIV/0! | W40: =V40/F40 -> #DIV/0!
...

Sheet 各班级出勤情况
A1: 听课班级 | B1: 出勤率
A2: {=INDEX(原始数据!B:B,SMALL(IF(原始数据!H$4:H$41=B2,ROW(B$4:B$41),4^8),COUNTIF(B$2:B2,B2)))} -> #DIV/0! | B2: =LARGE(原始数据!$H$4:$H$41,ROW(B1)) -> #DIV/0!
A3: {=INDEX(原始数据!B:B,SMALL(IF(原始数据!H$4:H$41=B3,ROW(B$4:B$41),4^8),COUNTIF(B$2:B3,B3)))} -> #DIV/0! | B3: =LARGE(原始数据!$H$4:$H$41,ROW(B2)) -> #DIV/0!
A4: {=INDEX(原始数据!B:B,SMALL(IF(原始数据!H$4:H$41=B4,ROW(B$4:B$41),4^8),COUNTIF(B$2:B4,B4)))} -> #DIV/0! | B4: =LARGE(原始数据!$H$4:$H$41,ROW(B3)) -> #DIV/0!
A5: {=INDEX(原始数据!B:B,SMALL(IF(原始数据!H$4:H$41=B5,ROW(B$4:B$41),4^8),COUNTIF(B$2:B5,B5)))} -> #DIV/0! | B5: =LARGE(原始数据!$H$4:$H$41,ROW(B4)) -> #DIV/0!
A6: {=INDEX(原始数据!B:B,SMALL(IF(原始数据!H$4:H$41=B6,ROW(B$4:B$41),4^8),COUNTIF(B$2:B6,B6)))} -> #DIV/0! | B6: =LARGE(原始数据!$H$4:$H$41,ROW(B5)) -> #DIV/0!
A7: {=INDEX(原始数据!B:B,SMALL(IF(原始数据!H$4:H$41=B7,ROW(B$4:B$41),4^8),COUNTIF(B$2:B7,B7)))} -> #DIV/0! | B7: =LARGE(原始数据!$H$4:$H$41,ROW(B6)) -> #DIV/0!
A8: {=INDEX(原始数据!B:B,SMALL(IF(原始数据!H$4:H$41=B8,ROW(B$4:B$41),4^8),COUNTIF(B$2:B8,B8)))} -> #DIV/0! | B8: =LARGE(原始数据!$H$4:$H$41,ROW(B7)) -> #DIV/0!
A9: {=INDEX(原始数据!B:B,SMALL(IF(原始数据!H$4:H$41=B9,ROW(B$4:B$41),4^8),COUNTIF(B$2:B9,B9)))} -> #DIV/0! | B9: =LARGE(原始数据!$H$4:$H$41,ROW(B8)) -> #DIV/0!
A10: {=INDEX(原始数据!B:B,SMALL(IF(原始数据!H$4:H$41=B10,ROW(B$4:B$41),4^8),COUNTIF(B$2:B10,B10)))} -> #DIV/0! | B10: =LARGE(原始数据!$H$4:$H$41,ROW(B9)) -> #DIV/0!
A11: {=INDEX(原始数据!B:B,SMALL(IF(原始数据!H$4:H$41=B11,ROW(B$4:B$41),4^8),COUNTIF(B$2:B11,B11)))} -> #DIV/0! | B11: =LARGE(原始数据!$H$4:$H$41,ROW(B10)) -> #DIV/0!
A12: {=INDEX(原始数据!B:B,SMALL(IF(原始数据!H$4:H$41=B12,ROW(B$4:B$41),4^8),COUNTIF(B$2:B12,B12)))} -> #DIV/0! | B12: =LARGE(原始数据!$H$4:$H$41,ROW(B11)) -> #DIV/0!
A13: {=INDEX(原始数据!B:B,SMALL(IF(原始数据!H$4:H$41=B13,ROW(B$4:B$41),4^8),COUNTIF(B$2:B13,B13)))} -> #DIV/0! | B13: =LARGE(原始数据!$H$4:$H$41,ROW(B12)) -> #DIV/0!
... A39: {=INDEX(原始数据!B:B,SMALL(IF(原始数据!H$4:H$41=B39,ROW(B$4:B$41),4^8),COUNTIF(B$2:B39,B39)))} -> #DIV/0! | B39: =LARGE(原始数据!$H$4:$H$41,ROW(B38)) -> #DIV/0!

Sheet 各班级违纪情况
A1: 听课班级 | B1: 违纪率
A2: {=INDEX(原始数据!B:B,SMALL(IF(原始数据!T$4:T$41=B2,ROW(B$4:B$41),4^8),COUNTIF(B$2:B2,B2)))} -> #DIV/0! | B2: =LARGE(原始数据!$T$4:$T$41,ROW(B1)) -> #DIV/0!
A3: {=INDEX(原始数据!B:B,SMALL(IF(原始数据!T$4:T$41=B3,ROW(B$4:B$41),4^8),COUNTIF(B$2:B3,B3)))} -> #DIV/0! | B3: =LARGE(原始数据!$T$4:$T$41,ROW(B2)) -> #DIV/0!
A4: {=INDEX(原始数据!B:B,SMALL(IF(原始数据!T$4:T$41=B4,ROW(B$4:B$41),4^8),COUNTIF(B$2:B4,B4)))} -> #DIV/0! | B4: =LARGE(原始数据!$T$4:$T$41,ROW(B3)) -> #DIV/0!
A5: {=INDEX(原始数据!B:B,SMALL(IF(原始数据!T$4:T$41=B5,ROW(B$4:B$41),4^8),COUNTIF(B$2:B5,B5)))} -> #DIV/0! | B5: =LARGE(原始数据!$T$4:$T$41,ROW(B4)) -> #DIV/0!
A6: {=INDEX(原始数据!B:B,SMALL(IF(原始数据!T$4:T$41=B6,ROW(B$4:B$41),4^8),COUNTIF(B$2:B6,B6)))} -> #DIV/0! | B6: =LARGE(原始数据!$T$4:$T$41,ROW(B5)) -> #DIV/0!
A7: {=INDEX(原始数据!B:B,SMALL(IF(原始数据!T$4:T$41=B7,ROW(B$4:B$41),4^8),COUNTIF(B$2:B7,B7)))} -> #DIV/0! | B7: =LARGE(原始数据!$T$4:$T$41,ROW(B6)) -> #DIV/0!
A8: {=INDEX(原始数据!B:B,SMALL(IF(原始数据!T$4:T$41=B8,ROW(B$4:B$41),4^8),COUNTIF(B$2:B8,B8)))} -> #DIV/0! | B8: =LARGE(原始数据!$T$4:$T$41,ROW(B7)) -> #DIV/0!
A9: {=INDEX(原始数据!B:B,SMALL(IF(原始数据!T$4:T$41=B9,ROW(B$4:B$41),4^8),COUNTIF(B$2:B9,B9)))} -> #DIV/0! | B9: =LARGE(原始数据!$T$4:$T$41,ROW(B8)) -> #DIV/0!
A10: {=INDEX(原始数据!B:B,SMALL(IF(原始数据!T$4:T$41=B10,ROW(B$4:B$41),4^8),COUNTIF(B$2:B10,B10)))} -> #DIV/0! | B10: =LARGE(原始数据!$T$4:$T$41,ROW(B9)) -> #DIV/0!
A11: {=INDEX(原始数据!B:B,SMALL(IF(原始数据!T$4:T$41=B11,ROW(B$4:B$41),4^8),COUNTIF(B$2:B11,B11)))} -> #DIV/0! | B11: =LARGE(原始数据!$T$4:$T$41,ROW(B10)) -> #DIV/0!
A12: {=INDEX(原始数据!B:B,SMALL(IF(原始数据!T$4:T$41=B12,ROW(B$4:B$41),4^8),COUNTIF(B$2:B12,B12)))} -> #DIV/0! | B12: =LARGE(原始数据!$T$4:$T$41,ROW(B11)) -> #DIV/0!
A13: {=INDEX(原始数据!B:B,SMALL(IF(原始数据!T$4:T$41=B13,ROW(B$4:B$41),4^8),COUNTIF(B$2:B13,B13)))} -> #DIV/0! | B13: =LARGE(原始数据!$T$4:$T$41,ROW(B12)) -> #DIV/0!
... A39: {=INDEX(原始数据!B:B,SMALL(IF(原始数据!T$4:T$41=B39,ROW(B$4:B$41),4^8),COUNTIF(B$2:B39,B39)))} -> #DIV/0! | B39: =LARGE(原始数据!$T$4:$T$41,ROW(B38)) -> #DIV/0!

Sheet 各班级迟到情况
A1: 听课班级 | B1: 迟到人数
A2: {=INDEX(原始数据!B:B,SMALL(IF(原始数据!I$4:I$41=B2,ROW(B$4:B$41),4^8),COUNTIF(B$2:B2,B2)))} -> #NUM! | B2: =LARGE(原始数据!$I$4:$I$41,ROW(B1)) -> #NUM!
A3: {=INDEX(原始数据!B:B,SMALL(IF(原始数据!I$4:I$41=B3,ROW(B$4:B$41),4^8),COUNTIF(B$2:B3,B3)))} -> #NUM! | B3: =LARGE(原始数据!$I$4:$I$41,ROW(B2)) -> #NUM!
A4: {=INDEX(原始数据!B:B,SMALL(IF(原始数据!I$4:I$41=B4,ROW(B$4:B$41),4^8),COUNTIF(B$2:B4,B4)))} -> #NUM! | B4: =LARGE(原始数据!$I$4:$I$41,ROW(B3)) -> #NUM!
A5: {=INDEX(原始数据!B:B,SMALL(IF(原始数据!I$4:I$41=B5,ROW(B$4:B$41),4^8),COUNTIF(B$2:B5,B5)))} -> #NUM! | B5: =LARGE(原始数据!$I$4:$I$41,ROW(B4)) -> #NUM!
A6: {=INDEX(原始数据!B:B,SMALL(IF(原始数据!I$4:I$41=B6,ROW(B$4:B$41),4^8),COUNTIF(B$2:B6,B6)))} -> #NUM! | B6: =LARGE(原始数据!$I$4:$I$41,ROW(B5)) -> #NUM!
A7: {=INDEX(原始数据!B:B,SMALL(IF(原始数据!I$4:I$41=B7,ROW(B$4:B$41),4^8),COUNTIF(B$2:B7,B7)))} -> #NUM! | B7: =LARGE(原始数据!$I$4:$I$41,ROW(B6)) -> #NUM!
A8: {=INDEX(原始数据!B:B,SMALL(IF(原始数据!I$4:I$41=B8,ROW(B$4:B$41),4^8),COUNTIF(B$2:B8,B8)))} -> #NUM! | B8: =LARGE(原始数据!$I$4:$I$41,ROW(B7)) -> #NUM!
A9: {=INDEX(原始数据!B:B,SMALL(IF(原始数据!I$4:I$41=B9,ROW(B$4:B$41),4^8),COUNTIF(B$2:B9,B9)))} -> #NUM! | B9: =LARGE(原始数据!$I$4:$I$41,ROW(B8)) -> #NUM!
A10: {=INDEX(原始数据!B:B,SMALL(IF(原始数据!I$4:I$41=B10,ROW(B$4:B$41),4^8),COUNTIF(B$2:B10,B10)))} -> #NUM! | B10: =LARGE(原始数据!$I$4:$I$41,ROW(B9)) -> #NUM!
A11: {=INDEX(原始数据!B:B,SMALL(IF(原始数据!I$4:I$41=B11,ROW(B$4:B$41),4^8),COUNTIF(B$2:B11,B11)))} -> #NUM! | B11: =LARGE(原始数据!$I$4:$I$41,ROW(B10)) -> #NUM!
A12: {=INDEX(原始数据!B:B,SMALL(IF(原始数据!I$4:I$41=B12,ROW(B$4:B$41),4^8),COUNTIF(B$2:B12,B12)))} -> #NUM! | B12: =LARGE(原始数据!$I$4:$I$41,ROW(B11)) -> #NUM!
A13: {=INDEX(原始数据!B:B,SMALL(IF(原始数据!I$4:I$41=B13,ROW(B$4:B$41),4^8),COUNTIF(B$2:B13,B13)))} -> #NUM! | B13: =LARGE(原始数据!$I$4:$I$41,ROW(B12)) -> #NUM!
... A39: {=INDEX(原始数据!B:B,SMALL(IF(原始数据!I$4:I$41=B39,ROW(B$4:B$41),4^8),COUNTIF(B$2:B39,B39)))} -> #NUM! | B39: =LARGE(原始数据!$I$4:$I$41,ROW(B38)) -> #NUM!

Sheet 25级出勤情况  
A1: 听课班级 | B1: 出勤率
A2: {=INDEX(原始数据!B:B,SMALL(IF(原始数据!H$4:H$15=B2,ROW(B$4:B$15),4^8),COUNTIF(B$2:B2,B2)))} -> #DIV/0! | B2: =LARGE(原始数据!$H$4:$H$15,ROW(B1)) -> #DIV/0!
A3: {=INDEX(原始数据!B:B,SMALL(IF(原始数据!H$4:H$15=B3,ROW(B$4:B$15),4^8),COUNTIF(B$2:B3,B3)))} -> #DIV/0! | B3: =LARGE(原始数据!$H$4:$H$15,ROW(B2)) -> #DIV/0!
A4: {=INDEX(原始数据!B:B,SMALL(IF(原始数据!H$4:H$15=B4,ROW(B$4:B$15),4^8),COUNTIF(B$2:B4,B4)))} -> #DIV/0! | B4: =LARGE(原始数据!$H$4:$H$15,ROW(B3)) -> #DIV/0!
A5: {=INDEX(原始数据!B:B,SMALL(IF(原始数据!H$4:H$15=B5,ROW(B$4:B$15),4^8),COUNTIF(B$2:B5,B5)))} -> #DIV/0! | B5: =LARGE(原始数据!$H$4:$H$15,ROW(B4)) -> #DIV/0!
A6: {=INDEX(原始数据!B:B,SMALL(IF(原始数据!H$4:H$15=B6,ROW(B$4:B$15),4^8),COUNTIF(B$2:B6,B6)))} -> #DIV/0! | B6: =LARGE(原始数据!$H$4:$H$15,ROW(B5)) -> #DIV/0!
A7: {=INDEX(原始数据!B:B,SMALL(IF(原始数据!H$4:H$15=B7,ROW(B$4:B$15),4^8),COUNTIF(B$2:B7,B7)))} -> #DIV/0! | B7: =LARGE(原始数据!$H$4:$H$15,ROW(B6)) -> #DIV/0!
A8: {=INDEX(原始数据!B:B,SMALL(IF(原始数据!H$4:H$15=B8,ROW(B$4:B$15),4^8),COUNTIF(B$2:B8,B8)))} -> #DIV/0! | B8: =LARGE(原始数据!$H$4:$H$15,ROW(B7)) -> #DIV/0!
A9: {=INDEX(原始数据!B:B,SMALL(IF(原始数据!H$4:H$15=B9,ROW(B$4:B$15),4^8),COUNTIF(B$2:B9,B9)))} -> #DIV/0! | B9: =LARGE(原始数据!$H$4:$H$15,ROW(B8)) -> #DIV/0!
A10: {=INDEX(原始数据!B:B,SMALL(IF(原始数据!H$4:H$15=B10,ROW(B$4:B$15),4^8),COUNTIF(B$2:B10,B10)))} -> #DIV/0! | B10: =LARGE(原始数据!$H$4:$H$15,ROW(B9)) -> #DIV/0!
A11: {=INDEX(原始数据!B:B,SMALL(IF(原始数据!H$4:H$15=B11,ROW(B$4:B$15),4^8),COUNTIF(B$2:B11,B11)))} -> #DIV/0! | B11: =LARGE(原始数据!$H$4:$H$15,ROW(B10)) -> #DIV/0!
A12: {=INDEX(原始数据!B:B,SMALL(IF(原始数据!H$4:H$15=B12,ROW(B$4:B$15),4^8),COUNTIF(B$2:B12,B12)))} -> #DIV/0! | B12: =LARGE(原始数据!$H$4:$H$15,ROW(B11)) -> #DIV/0!
A13: {=INDEX(原始数据!B:B,SMALL(IF(原始数据!H$4:H$15=B13,ROW(B$4:B$15),4^8),COUNTIF(B$2:B13,B13)))} -> #DIV/0! | B13: =LARGE(原始数据!$H$4:$H$15,ROW(B12)) -> #DIV/0!

Sheet 25级违纪情况  
A1: 听课班级 | B1: 违纪率
A2: {=INDEX(原始数据!B:B,SMALL(IF(原始数据!T$4:T$15=B2,ROW(T$4:T$15),4^8),COUNTIF(B$2:B2,B2)))} -> #DIV/0! | B2: =LARGE(原始数据!$T$4:$T$15,ROW(B1)) -> #DIV/0!
A3: {=INDEX(原始数据!B:B,SMALL(IF(原始数据!T$4:T$15=B3,ROW(T$4:T$15),4^8),COUNTIF(B$2:B3,B3)))} -> #DIV/0! | B3: =LARGE(原始数据!$T$4:$T$15,ROW(B2)) -> #DIV/0!
A4: {=INDEX(原始数据!B:B,SMALL(IF(原始数据!T$4:T$15=B4,ROW(T$4:T$15),4^8),COUNTIF(B$2:B4,B4)))} -> #DIV/0! | B4: =LARGE(原始数据!$T$4:$T$15,ROW(B3)) -> #DIV/0!
A5: {=INDEX(原始数据!B:B,SMALL(IF(原始数据!T$4:T$15=B5,ROW(T$4:T$15),4^8),COUNTIF(B$2:B5,B5)))} -> #DIV/0! | B5: =LARGE(原始数据!$T$4:$T$15,ROW(B4)) -> #DIV/0!
A6: {=INDEX(原始数据!B:B,SMALL(IF(原始数据!T$4:T$15=B6,ROW(T$4:T$15),4^8),COUNTIF(B$2:B6,B6)))} -> #DIV/0! | B6: =LARGE(原始数据!$T$4:$T$15,ROW(B5)) -> #DIV/0!
A7: {=INDEX(原始数据!B:B,SMALL(IF(原始数据!T$4:T$15=B7,ROW(T$4:T$15),4^8),COUNTIF(B$2:B7,B7)))} -> #DIV/0! | B7: =LARGE(原始数据!$T$4:$T$15,ROW(B6)) -> #DIV/0!
A8: {=INDEX(原始数据!B:B,SMALL(IF(原始数据!T$4:T$15=B8,ROW(T$4:T$15),4^8),COUNTIF(B$2:B8,B8)))} -> #DIV/0! | B8: =LARGE(原始数据!$T$4:$T$15,ROW(B7)) -> #DIV/0!
A9: {=INDEX(原始数据!B:B,SMALL(IF(原始数据!T$4:T$15=B9,ROW(T$4:T$15),4^8),COUNTIF(B$2:B9,B9)))} -> #DIV/0! | B9: =LARGE(原始数据!$T$4:$T$15,ROW(B8)) -> #DIV/0!
A10: {=INDEX(原始数据!B:B,SMALL(IF(原始数据!T$4:T$15=B10,ROW(T$4:T$15),4^8),COUNTIF(B$2:B10,B10)))} -> #DIV/0! | B10: =LARGE(原始数据!$T$4:$T$15,ROW(B9)) -> #DIV/0!
A11: {=INDEX(原始数据!B:B,SMALL(IF(原始数据!T$4:T$15=B11,ROW(T$4:T$15),4^8),COUNTIF(B$2:B11,B11)))} -> #DIV/0! | B11: =LARGE(原始数据!$T$4:$T$15,ROW(B10)) -> #DIV/0!
A12: {=INDEX(原始数据!B:B,SMALL(IF(原始数据!T$4:T$15=B12,ROW(T$4:T$15),4^8),COUNTIF(B$2:B12,B12)))} -> #DIV/0! | B12: =LARGE(原始数据!$T$4:$T$15,ROW(B11)) -> #DIV/0!
A13: {=INDEX(原始数据!B:B,SMALL(IF(原始数据!T$4:T$15=B13,ROW(T$4:T$15),4^8),COUNTIF(B$2:B13,B13)))} -> #DIV/0! | B13: =LARGE(原始数据!$T$4:$T$15,ROW(B12)) -> #DIV/0!

Sheet 25级迟到情况
A1: 听课班级 | B1: 迟到率
A2: {=INDEX(原始数据!B:B,SMALL(IF(原始数据!J$4:J$15=B2,ROW(J$4:J$15),4^8),COUNTIF(B$2:B2,B2)))} -> #DIV/0! | B2: =LARGE(原始数据!$J$4:$J$15,ROW(B1)) -> #DIV/0!
A3: {=INDEX(原始数据!B:B,SMALL(IF(原始数据!J$4:J$15=B3,ROW(J$4:J$15),4^8),COUNTIF(B$2:B3,B3)))} -> #DIV/0! | B3: =LARGE(原始数据!$J$4:$J$15,ROW(B2)) -> #DIV/0!
A4: {=INDEX(原始数据!B:B,SMALL(IF(原始数据!J$4:J$15=B4,ROW(J$4:J$15),4^8),COUNTIF(B$2:B4,B4)))} -> #DIV/0! | B4: =LARGE(原始数据!$J$4:$J$15,ROW(B3)) -> #DIV/0!
A5: {=INDEX(原始数据!B:B,SMALL(IF(原始数据!J$4:J$15=B5,ROW(J$4:J$15),4^8),COUNTIF(B$2:B5,B5)))} -> #DIV/0! | B5: =LARGE(原始数据!$J$4:$J$15,ROW(B4)) -> #DIV/0!
A6: {=INDEX(原始数据!B:B,SMALL(IF(原始数据!J$4:J$15=B6,ROW(J$4:J$15),4^8),COUNTIF(B$2:B6,B6)))} -> #DIV/0! | B6: =LARGE(原始数据!$J$4:$J$15,ROW(B5)) -> #DIV/0!
A7: {=INDEX(原始数据!B:B,SMALL(IF(原始数据!J$4:J$15=B7,ROW(J$4:J$15),4^8),COUNTIF(B$2:B7,B7)))} -> #DIV/0! | B7: =LARGE(原始数据!$J$4:$J$15,ROW(B6)) -> #DIV/0!
A8: {=INDEX(原始数据!B:B,SMALL(IF(原始数据!J$4:J$15=B8,ROW(J$4:J$15),4^8),COUNTIF(B$2:B8,B8)))} -> #DIV/0! | B8: =LARGE(原始数据!$J$4:$J$15,ROW(B7)) -> #DIV/0!
A9: {=INDEX(原始数据!B:B,SMALL(IF(原始数据!J$4:J$15=B9,ROW(J$4:J$15),4^8),COUNTIF(B$2:B9,B9)))} -> #DIV/0! | B9: =LARGE(原始数据!$J$4:$J$15,ROW(B8)) -> #DIV/0!
A10: {=INDEX(原始数据!B:B,SMALL(IF(原始数据!J$4:J$15=B10,ROW(J$4:J$15),4^8),COUNTIF(B$2:B10,B10)))} -> #DIV/0! | B10: =LARGE(原始数据!$J$4:$J$15,ROW(B9)) -> #DIV/0!
A11: {=INDEX(原始数据!B:B,SMALL(IF(原始数据!J$4:J$15=B11,ROW(J$4:J$15),4^8),COUNTIF(B$2:B11,B11)))} -> #DIV/0! | B11: =LARGE(原始数据!$J$4:$J$15,ROW(B10)) -> #DIV/0!
A12: {=INDEX(原始数据!B:B,SMALL(IF(原始数据!J$4:J$15=B12,ROW(J$4:J$15),4^8),COUNTIF(B$2:B12,B12)))} -> #DIV/0! | B12: =LARGE(原始数据!$J$4:$J$15,ROW(B11)) -> #DIV/0!
A13: {=INDEX(原始数据!B:B,SMALL(IF(原始数据!J$4:J$15=B13,ROW(J$4:J$15),4^8),COUNTIF(B$2:B13,B13)))} -> #DIV/0! | B13: =LARGE(原始数据!$J$4:$J$15,ROW(B12)) -> #DIV/0!

Sheet 23级出勤情况 
A1: 听课班级 | B1: 出勤率
A2: {=INDEX(原始数据!B:B,SMALL(IF(原始数据!H$16:H$28=B2,ROW(B$16:B$28),4^8),COUNTIF(B$2:B2,B2)))} -> #DIV/0! | B2: =LARGE(原始数据!$H$16:$H$28,ROW(B1)) -> #DIV/0!
A3: {=INDEX(原始数据!B:B,SMALL(IF(原始数据!H$16:H$28=B3,ROW(B$16:B$28),4^8),COUNTIF(B$2:B3,B3)))} -> #DIV/0! | B3: =LARGE(原始数据!$H$16:$H$28,ROW(B2)) -> #DIV/0!
A4: {=INDEX(原始数据!B:B,SMALL(IF(原始数据!H$16:H$28=B4,ROW(B$16:B$28),4^8),COUNTIF(B$2:B4,B4)))} -> #DIV/0! | B4: =LARGE(原始数据!$H$16:$H$28,ROW(B3)) -> #DIV/0!
A5: {=INDEX(原始数据!B:B,SMALL(IF(原始数据!H$16:H$28=B5,ROW(B$16:B$28),4^8),COUNTIF(B$2:B5,B5)))} -> #DIV/0! | B5: =LARGE(原始数据!$H$16:$H$28,ROW(B4)) -> #DIV/0!
A6: {=INDEX(原始数据!B:B,SMALL(IF(原始数据!H$16:H$28=B6,ROW(B$16:B$28),4^8),COUNTIF(B$2:B6,B6)))} -> #DIV/0! | B6: =LARGE(原始数据!$H$16:$H$28,ROW(B5)) -> #DIV/0!
A7: {=INDEX(原始数据!B:B,SMALL(IF(原始数据!H$16:H$28=B7,ROW(B$16:B$28),4^8),COUNTIF(B$2:B7,B7)))} -> #DIV/0! | B7: =LARGE(原始数据!$H$16:$H$28,ROW(B6)) -> #DIV/0!
A8: {=INDEX(原始数据!B:B,SMALL(IF(原始数据!H$16:H$28=B8,ROW(B$16:B$28),4^8),COUNTIF(B$2:B8,B8)))} -> #DIV/0! | B8: =LARGE(原始数据!$H$16:$H$28,ROW(B7)) -> #DIV/0!
A9: {=INDEX(原始数据!B:B,SMALL(IF(原始数据!H$16:H$28=B9,ROW(B$16:B$28),4^8),COUNTIF(B$2:B9,B9)))} -> #DIV/0! | B9: =LARGE(原始数据!$H$16:$H$28,ROW(B8)) -> #DIV/0!
A10: {=INDEX(原始数据!B:B,SMALL(IF(原始数据!H$16:H$28=B10,ROW(B$16:B$28),4^8),COUNTIF(B$2:B10,B10)))} -> #DIV/0! | B10: =LARGE(原始数据!$H$16:$H$28,ROW(B9)) -> #DIV/0!
A11: {=INDEX(原始数据!B:B,SMALL(IF(原始数据!H$16:H$28=B11,ROW(B$16:B$28),4^8),COUNTIF(B$2:B11,B11)))} -> #DIV/0! | B11: =LARGE(原始数据!$H$16:$H$28,ROW(B10)) -> #DIV/0!
A12: {=INDEX(原始数据!B:B,SMALL(IF(原始数据!H$16:H$28=B12,ROW(B$16:B$28),4^8),COUNTIF(B$2:B12,B12)))} -> #DIV/0! | B12: =LARGE(原始数据!$H$16:$H$28,ROW(B11)) -> #DIV/0!
A13: {=INDEX(原始数据!B:B,SMALL(IF(原始数据!H$16:H$28=B13,ROW(B$16:B$28),4^8),COUNTIF(B$2:B13,B13)))} -> #DIV/0! | B13: =LARGE(原始数据!$H$16:$H$28,ROW(B12)) -> #DIV/0!
A14: {=INDEX(原始数据!B:B,SMALL(IF(原始数据!H$16:H$28=B14,ROW(B$16:B$28),4^8),COUNTIF(B$2:B14,B14)))} -> #DIV/0! | B14: =LARGE(原始数据!$H$16:$H$28,ROW(B13)) -> #DIV/0!

Sheet 23级违纪情况 
A1: 听课班级 | B1: 违纪率
A2: {=INDEX(原始数据!B:B,SMALL(IF(原始数据!T$16:T$28=B2,ROW(T$16:T$28),4^8),COUNTIF(B$2:B2,B2)))} -> #DIV/0! | B2: =LARGE(原始数据!$T$16:$T$28,ROW(B1)) -> #DIV/0!
A3: {=INDEX(原始数据!B:B,SMALL(IF(原始数据!T$16:T$28=B3,ROW(T$16:T$28),4^8),COUNTIF(B$2:B3,B3)))} -> #DIV/0! | B3: =LARGE(原始数据!$T$16:$T$28,ROW(B2)) -> #DIV/0!
A4: {=INDEX(原始数据!B:B,SMALL(IF(原始数据!T$16:T$28=B4,ROW(T$16:T$28),4^8),COUNTIF(B$2:B4,B4)))} -> #DIV/0! | B4: =LARGE(原始数据!$T$16:$T$28,ROW(B3)) -> #DIV/0!
A5: {=INDEX(原始数据!B:B,SMALL(IF(原始数据!T$16:T$28=B5,ROW(T$16:T$28),4^8),COUNTIF(B$2:B5,B5)))} -> #DIV/0! | B5: =LARGE(原始数据!$T$16:$T$28,ROW(B4)) -> #DIV/0!
A6: {=INDEX(原始数据!B:B,SMALL(IF(原始数据!T$16:T$28=B6,ROW(T$16:T$28),4^8),COUNTIF(B$2:B6,B6)))} -> #DIV/0! | B6: =LARGE(原始数据!$T$16:$T$28,ROW(B5)) -> #DIV/0!
A7: {=INDEX(原始数据!B:B,SMALL(IF(原始数据!T$16:T$28=B7,ROW(T$16:T$28),4^8),COUNTIF(B$2:B7,B7)))} -> #DIV/0! | B7: =LARGE(原始数据!$T$16:$T$28,ROW(B6)) -> #DIV/0!
A8: {=INDEX(原始数据!B:B,SMALL(IF(原始数据!T$16:T$28=B8,ROW(T$16:T$28),4^8),COUNTIF(B$2:B8,B8)))} -> #DIV/0! | B8: =LARGE(原始数据!$T$16:$T$28,ROW(B7)) -> #DIV/0!
A9: {=INDEX(原始数据!B:B,SMALL(IF(原始数据!T$16:T$28=B9,ROW(T$16:T$28),4^8),COUNTIF(B$2:B9,B9)))} -> #DIV/0! | B9: =LARGE(原始数据!$T$16:$T$28,ROW(B8)) -> #DIV/0!
A10: {=INDEX(原始数据!B:B,SMALL(IF(原始数据!T$16:T$28=B10,ROW(T$16:T$28),4^8),COUNTIF(B$2:B10,B10)))} -> #DIV/0! | B10: =LARGE(原始数据!$T$16:$T$28,ROW(B9)) -> #DIV/0!
A11: {=INDEX(原始数据!B:B,SMALL(IF(原始数据!T$16:T$28=B11,ROW(T$16:T$28),4^8),COUNTIF(B$2:B11,B11)))} -> #DIV/0! | B11: =LARGE(原始数据!$T$16:$T$28,ROW(B10)) -> #DIV/0!
A12: {=INDEX(原始数据!B:B,SMALL(IF(原始数据!T$16:T$28=B12,ROW(T$16:T$28),4^8),COUNTIF(B$2:B12,B12)))} -> #DIV/0! | B12: =LARGE(原始数据!$T$16:$T$28,ROW(B11)) -> #DIV/0!
A13: {=INDEX(原始数据!B:B,SMALL(IF(原始数据!T$16:T$28=B13,ROW(T$16:T$28),4^8),COUNTIF(B$2:B13,B13)))} -> #DIV/0! | B13: =LARGE(原始数据!$T$16:$T$28,ROW(B12)) -> #DIV/0!
A14: {=INDEX(原始数据!B:B,SMALL(IF(原始数据!T$16:T$28=B14,ROW(T$16:T$28),4^8),COUNTIF(B$2:B14,B14)))} -> #DIV/0! | B14: =LARGE(原始数据!$T$16:$T$28,ROW(B13)) -> #DIV/0!

Sheet 23级迟到情况
A1: 听课班级 | B1: 迟到率
A2: {=INDEX(原始数据!B:B,SMALL(IF(原始数据!J$16:J$28=B2,ROW(J$16:J$28),4^8),COUNTIF(B$2:B2,B2)))} -> #DIV/0! | B2: =LARGE(原始数据!$J$16:$J$28,ROW(B1)) -> #DIV/0!
A3: {=INDEX(原始数据!B:B,SMALL(IF(原始数据!J$16:J$28=B3,ROW(J$16:J$28),4^8),COUNTIF(B$2:B3,B3)))} -> #DIV/0! | B3: =LARGE(原始数据!$J$16:$J$28,ROW(B2)) -> #DIV/0!
A4: {=INDEX(原始数据!B:B,SMALL(IF(原始数据!J$16:J$28=B4,ROW(J$16:J$28),4^8),COUNTIF(B$2:B4,B4)))} -> #DIV/0! | B4: =LARGE(原始数据!$J$16:$J$28,ROW(B3)) -> #DIV/0!
A5: {=INDEX(原始数据!B:B,SMALL(IF(原始数据!J$16:J$28=B5,ROW(J$16:J$28),4^8),COUNTIF(B$2:B5,B5)))} -> #DIV/0! | B5: =LARGE(原始数据!$J$16:$J$28,ROW(B4)) -> #DIV/0!
A6: {=INDEX(原始数据!B:B,SMALL(IF(原始数据!J$16:J$28=B6,ROW(J$16:J$28),4^8),COUNTIF(B$2:B6,B6)))} -> #DIV/0! | B6: =LARGE(原始数据!$J$16:$J$28,ROW(B5)) -> #DIV/0!
A7: {=INDEX(原始数据!B:B,SMALL(IF(原始数据!J$16:J$28=B7,ROW(J$16:J$28),4^8),COUNTIF(B$2:B7,B7)))} -> #DIV/0! | B7: =LARGE(原始数据!$J$16:$J$28,ROW(B6)) -> #DIV/0!
A8: {=INDEX(原始数据!B:B,SMALL(IF(原始数据!J$16:J$28=B8,ROW(J$16:J$28),4^8),COUNTIF(B$2:B8,B8)))} -> #DIV/0! | B8: =LARGE(原始数据!$J$16:$J$28,ROW(B7)) -> #DIV/0!
A9: {=INDEX(原始数据!B:B,SMALL(IF(原始数据!J$16:J$28=B9,ROW(J$16:J$28),4^8),COUNTIF(B$2:B9,B9)))} -> #DIV/0! | B9: =LARGE(原始数据!$J$16:$J$28,ROW(B8)) -> #DIV/0!
A10: {=INDEX(原始数据!B:B,SMALL(IF(原始数据!J$16:J$28=B10,ROW(J$16:J$28),4^8),COUNTIF(B$2:B10,B10)))} -> #DIV/0! | B10: =LARGE(原始数据!$J$16:$J$28,ROW(B9)) -> #DIV/0!
A11: {=INDEX(原始数据!B:B,SMALL(IF(原始数据!J$16:J$28=B11,ROW(J$16:J$28),4^8),COUNTIF(B$2:B11,B11)))} -> #DIV/0! | B11: =LARGE(原始数据!$J$16:$J$28,ROW(B10)) -> #DIV/0!
A12: {=INDEX(原始数据!B:B,SMALL(IF(原始数据!J$16:J$28=B12,ROW(J$16:J$28),4^8),COUNTIF(B$2:B12,B12)))} -> #DIV/0! | B12: =LARGE(原始数据!$J$16:$J$28,ROW(B11)) -> #DIV/0!
A13: {=INDEX(原始数据!B:B,SMALL(IF(原始数据!J$16:J$28=B13,ROW(J$16:J$28),4^8),COUNTIF(B$2:B13,B13)))} -> #DIV/0! | B13: =LARGE(原始数据!$J$16:$J$28,ROW(B12)) -> #DIV/0!
A14: {=INDEX(原始数据!B:B,SMALL(IF(原始数据!J$16:J$28=B14,ROW(J$16:J$28),4^8),COUNTIF(B$2:B14,B14)))} -> #DIV/0! | B14: =LARGE(原始数据!$J$16:$J$28,ROW(B13)) -> #DIV/0!

Sheet 24级出勤情况 
A1: 听课班级 | B1: 出勤率
A2: {=INDEX(原始数据!B:B,SMALL(IF(原始数据!H$29:H$41=B2,ROW(B$29:B$41),4^8),COUNTIF(B$2:B2,B2)))} -> #DIV/0! | B2: =LARGE(原始数据!$H$29:$H$41,ROW(B1)) -> #DIV/0!
A3: {=INDEX(原始数据!B:B,SMALL(IF(原始数据!H$29:H$41=B3,ROW(B$29:B$41),4^8),COUNTIF(B$2:B3,B3)))} -> #DIV/0! | B3: =LARGE(原始数据!$H$29:$H$41,ROW(B2)) -> #DIV/0!
A4: {=INDEX(原始数据!B:B,SMALL(IF(原始数据!H$29:H$41=B4,ROW(B$29:B$41),4^8),COUNTIF(B$2:B4,B4)))} -> #DIV/0! | B4: =LARGE(原始数据!$H$29:$H$41,ROW(B3)) -> #DIV/0!
A5: {=INDEX(原始数据!B:B,SMALL(IF(原始数据!H$29:H$41=B5,ROW(B$29:B$41),4^8),COUNTIF(B$2:B5,B5)))} -> #DIV/0! | B5: =LARGE(原始数据!$H$29:$H$41,ROW(B4)) -> #DIV/0!
A6: {=INDEX(原始数据!B:B,SMALL(IF(原始数据!H$29:H$41=B6,ROW(B$29:B$41),4^8),COUNTIF(B$2:B6,B6)))} -> #DIV/0! | B6: =LARGE(原始数据!$H$29:$H$41,ROW(B5)) -> #DIV/0!
A7: {=INDEX(原始数据!B:B,SMALL(IF(原始数据!H$29:H$41=B7,ROW(B$29:B$41),4^8),COUNTIF(B$2:B7,B7)))} -> #DIV/0! | B7: =LARGE(原始数据!$H$29:$H$41,ROW(B6)) -> #DIV/0!
A8: {=INDEX(原始数据!B:B,SMALL(IF(原始数据!H$29:H$41=B8,ROW(B$29:B$41),4^8),COUNTIF(B$2:B8,B8)))} -> #DIV/0! | B8: =LARGE(原始数据!$H$29:$H$41,ROW(B7)) -> #DIV/0!
A9: {=INDEX(原始数据!B:B,SMALL(IF(原始数据!H$29:H$41=B9,ROW(B$29:B$41),4^8),COUNTIF(B$2:B9,B9)))} -> #DIV/0! | B9: =LARGE(原始数据!$H$29:$H$41,ROW(B8)) -> #DIV/0!
A10: {=INDEX(原始数据!B:B,SMALL(IF(原始数据!H$29:H$41=B10,ROW(B$29:B$41),4^8),COUNTIF(B$2:B10,B10)))} -> #DIV/0! | B10: =LARGE(原始数据!$H$29:$H$41,ROW(B9)) -> #DIV/0!
A11: {=INDEX(原始数据!B:B,SMALL(IF(原始数据!H$29:H$41=B11,ROW(B$29:B$41),4^8),COUNTIF(B$2:B11,B11)))} -> #DIV/0! | B11: =LARGE(原始数据!$H$29:$H$41,ROW(B10)) -> #DIV/0!
A12: {=INDEX(原始数据!B:B,SMALL(IF(原始数据!H$29:H$41=B12,ROW(B$29:B$41),4^8),COUNTIF(B$2:B12,B12)))} -> #DIV/0! | B12: =LARGE(原始数据!$H$29:$H$41,ROW(B11)) -> #DIV/0!
A13: {=INDEX(原始数据!B:B,SMALL(IF(原始数据!H$29:H$41=B13,ROW(B$29:B$41),4^8),COUNTIF(B$2:B13,B13)))} -> #DIV/0! | B13: =LARGE(原始数据!$H$29:$H$41,ROW(B12)) -> #DIV/0!
A14: {=INDEX(原始数据!B:B,SMALL(IF(原始数据!H$29:H$41=B14,ROW(B$29:B$41),4^8),COUNTIF(B$2:B14,B14)))} -> #DIV/0! | B14: =LARGE(原始数据!$H$29:$H$41,ROW(B13)) -> #DIV/0!

Sheet 24级违纪情况 
A1: 听课班级 | B1: 违纪率
A2: {=INDEX(原始数据!B:B,SMALL(IF(原始数据!T$29:T$41=B2,ROW(T$29:T$41),4^8),COUNTIF(B$2:B2,B2)))} -> #DIV/0! | B2: =LARGE(原始数据!$T$29:$T$41,ROW(B1)) -> #DIV/0!
A3: {=INDEX(原始数据!B:B,SMALL(IF(原始数据!T$29:T$41=B3,ROW(T$29:T$41),4^8),COUNTIF(B$2:B3,B3)))} -> #DIV/0! | B3: =LARGE(原始数据!$T$29:$T$41,ROW(B2)) -> #DIV/0!
A4: {=INDEX(原始数据!B:B,SMALL(IF(原始数据!T$29:T$41=B4,ROW(T$29:T$41),4^8),COUNTIF(B$2:B4,B4)))} -> #DIV/0! | B4: =LARGE(原始数据!$T$29:$T$41,ROW(B3)) -> #DIV/0!
A5: {=INDEX(原始数据!B:B,SMALL(IF(原始数据!T$29:T$41=B5,ROW(T$29:T$41),4^8),COUNTIF(B$2:B5,B5)))} -> #DIV/0! | B5: =LARGE(原始数据!$T$29:$T$41,ROW(B4)) -> #DIV/0!
A6: {=INDEX(原始数据!B:B,SMALL(IF(原始数据!T$29:T$41=B6,ROW(T$29:T$41),4^8),COUNTIF(B$2:B6,B6)))} -> #DIV/0! | B6: =LARGE(原始数据!$T$29:$T$41,ROW(B5)) -> #DIV/0!
A7: {=INDEX(原始数据!B:B,SMALL(IF(原始数据!T$29:T$41=B7,ROW(T$29:T$41),4^8),COUNTIF(B$2:B7,B7)))} -> #DIV/0! | B7: =LARGE(原始数据!$T$29:$T$41,ROW(B6)) -> #DIV/0!
A8: {=INDEX(原始数据!B:B,SMALL(IF(原始数据!T$29:T$41=B8,ROW(T$29:T$41),4^8),COUNTIF(B$2:B8,B8)))} -> #DIV/0! | B8: =LARGE(原始数据!$T$29:$T$41,ROW(B7)) -> #DIV/0!
A9: {=INDEX(原始数据!B:B,SMALL(IF(原始数据!T$29:T$41=B9,ROW(T$29:T$41),4^8),COUNTIF(B$2:B9,B9)))} -> #DIV/0! | B9: =LARGE(原始数据!$T$29:$T$41,ROW(B8)) -> #DIV/0!
A10: {=INDEX(原始数据!B:B,SMALL(IF(原始数据!T$29:T$41=B10,ROW(T$29:T$41),4^8),COUNTIF(B$2:B10,B10)))} -> #DIV/0! | B10: =LARGE(原始数据!$T$29:$T$41,ROW(B9)) -> #DIV/0!
A11: {=INDEX(原始数据!B:B,SMALL(IF(原始数据!T$29:T$41=B11,ROW(T$29:T$41),4^8),COUNTIF(B$2:B11,B11)))} -> #DIV/0! | B11: =LARGE(原始数据!$T$29:$T$41,ROW(B10)) -> #DIV/0!
A12: {=INDEX(原始数据!B:B,SMALL(IF(原始数据!T$29:T$41=B12,ROW(T$29:T$41),4^8),COUNTIF(B$2:B12,B12)))} -> #DIV/0! | B12: =LARGE(原始数据!$T$29:$T$41,ROW(B11)) -> #DIV/0!
A13: {=INDEX(原始数据!B:B,SMALL(IF(原始数据!T$29:T$41=B13,ROW(T$29:T$41),4^8),COUNTIF(B$2:B13,B13)))} -> #DIV/0! | B13: =LARGE(原始数据!$T$29:$T$41,ROW(B12)) -> #DIV/0!
A14: {=INDEX(原始数据!B:B,SMALL(IF(原始数据!T$29:T$41=B14,ROW(T$29:T$41),4^8),COUNTIF(B$2:B14,B14)))} -> #DIV/0! | B14: =LARGE(原始数据!$T$29:$T$41,ROW(B13)) -> #DIV/0!

Sheet 24级迟到情况
A1: 听课班级 | B1: 迟到率
A2: {=INDEX(原始数据!B:B,SMALL(IF(原始数据!J$29:J$41=B2,ROW(J$29:J$41),4^8),COUNTIF(B$2:B2,B2)))} -> #DIV/0! | B2: =LARGE(原始数据!$J$29:$J$41,ROW(B1)) -> #DIV/0!
A3: {=INDEX(原始数据!B:B,SMALL(IF(原始数据!J$29:J$41=B3,ROW(J$29:J$41),4^8),COUNTIF(B$2:B3,B3)))} -> #DIV/0! | B3: =LARGE(原始数据!$J$29:$J$41,ROW(B2)) -> #DIV/0!
A4: {=INDEX(原始数据!B:B,SMALL(IF(原始数据!J$29:J$41=B4,ROW(J$29:J$41),4^8),COUNTIF(B$2:B4,B4)))} -> #DIV/0! | B4: =LARGE(原始数据!$J$29:$J$41,ROW(B3)) -> #DIV/0!
A5: {=INDEX(原始数据!B:B,SMALL(IF(原始数据!J$29:J$41=B5,ROW(J$29:J$41),4^8),COUNTIF(B$2:B5,B5)))} -> #DIV/0! | B5: =LARGE(原始数据!$J$29:$J$41,ROW(B4)) -> #DIV/0!
A6: {=INDEX(原始数据!B:B,SMALL(IF(原始数据!J$29:J$41=B6,ROW(J$29:J$41),4^8),COUNTIF(B$2:B6,B6)))} -> #DIV/0! | B6: =LARGE(原始数据!$J$29:$J$41,ROW(B5)) -> #DIV/0!
A7: {=INDEX(原始数据!B:B,SMALL(IF(原始数据!J$29:J$41=B7,ROW(J$29:J$41),4^8),COUNTIF(B$2:B7,B7)))} -> #DIV/0! | B7: =LARGE(原始数据!$J$29:$J$41,ROW(B6)) -> #DIV/0!
A8: {=INDEX(原始数据!B:B,SMALL(IF(原始数据!J$29:J$41=B8,ROW(J$29:J$41),4^8),COUNTIF(B$2:B8,B8)))} -> #DIV/0! | B8: =LARGE(原始数据!$J$29:$J$41,ROW(B7)) -> #DIV/0!
A9: {=INDEX(原始数据!B:B,SMALL(IF(原始数据!J$29:J$41=B9,ROW(J$29:J$41),4^8),COUNTIF(B$2:B9,B9)))} -> #DIV/0! | B9: =LARGE(原始数据!$J$29:$J$41,ROW(B8)) -> #DIV/0!
A10: {=INDEX(原始数据!B:B,SMALL(IF(原始数据!J$29:J$41=B10,ROW(J$29:J$41),4^8),COUNTIF(B$2:B10,B10)))} -> #DIV/0! | B10: =LARGE(原始数据!$J$29:$J$41,ROW(B9)) -> #DIV/0!
A11: {=INDEX(原始数据!B:B,SMALL(IF(原始数据!J$29:J$41=B11,ROW(J$29:J$41),4^8),COUNTIF(B$2:B11,B11)))} -> #DIV/0! | B11: =LARGE(原始数据!$J$29:$J$41,ROW(B10)) -> #DIV/0!
A12: {=INDEX(原始数据!B:B,SMALL(IF(原始数据!J$29:J$41=B12,ROW(J$29:J$41),4^8),COUNTIF(B$2:B12,B12)))} -> #DIV/0! | B12: =LARGE(原始数据!$J$29:$J$41,ROW(B11)) -> #DIV/0!
A13: {=INDEX(原始数据!B:B,SMALL(IF(原始数据!J$29:J$41=B13,ROW(J$29:J$41),4^8),COUNTIF(B$2:B13,B13)))} -> #DIV/0! | B13: =LARGE(原始数据!$J$29:$J$41,ROW(B12)) -> #DIV/0!
A14: {=INDEX(原始数据!B:B,SMALL(IF(原始数据!J$29:J$41=B14,ROW(J$29:J$41),4^8),COUNTIF(B$2:B14,B14)))} -> #DIV/0! | B14: =LARGE(原始数据!$J$29:$J$41,ROW(B13)) -> #DIV/0!
